Workbook

Sheet Consumables Classification
A1: Row in Sheet1 | B1: Box | C1: Box category | D1: Sub-category | E1: Item | F1: Qty | G1: Classification | H1: Basis | I1: Owner | J1: Procure from | K1: PR raised | L1: PR number | M1: Procurement status | N1: Mobile / Stationary
A2: 1 | B2: 10 | C2: Power & Switching | D2: 10-A Fuses | E2: Fuse - ANM 250 A / 70 V (ANM70V-250A) - robot main | F2: 3 | G2: Consumable | H2: Fuse - single-use protection element | I2: Badri | J2: India | K2: No | M2: In stock | N2: Mobile (travels with robot)
A3: 2 | B3: 10 | C3: Power & Switching | D3: 10-A Fuses | E3: Fuse - ATN 20 A - travel motor, UR Controller, Planner Actuation, Planner Logic Buck | F3: 10.0 | G3: Consumable | H3: Fuse - single-use protection element | I3: Badri | J3: India | K3: No | M3: In stock | N3: Mobile (travels with robot)
A4: 3 | B4: 10 | C4: Power & Switching | D4: 10-A Fuses | E4: Fuse - ATN 10 A - steering motor | F4: 6 | G4: Consumable | H4: Fuse - single-use protection element | I4: Badri | J4: India | K4: No | M4: In stock | N4: Mobile (travels with robot)
A5: 4 | B5: 10 | C5: Power & Switching | D5: 10-A Fuses | E5: Fuse - ATM 40 A - lift kit | F5: 2 | G5: Consumable | H5: Fuse - single-use protection element | I5: Badri | J5: India | K5: No | M5: In stock | N5: Mobile (travels with robot)
A6: 5 | B6: 10 | C6: Power & Switching | D6: 10-A Fuses | E6: Fuse - ATN 15 A - control logic buck | F6: 2 | G6: Consumable | H6: Fuse - single-use protection element | I6: Badri | J6: India | K6: No | M6: In stock | N6: NY Stationary (stays in NY inventory)
A7: 6 | B7: 10 | C7: Power & Switching | D7: 10-A Fuses | E7: Fuse - ANM 125 A / 70 V (ANM70V-125A) - OST main | F7: 2 | G7: Consumable | H7: Fuse - single-use protection element | I7: Badri | J7: India | K7: No | M7: In stock | N7: Mobile (travels with robot)
A8: 7 | B8: 10 | C8: Power & Switching | D8: 10-A Fuses | E8: Fuse - Blade Mini 5 A - OST logic, TS sander actuation SMPS, TS sprayer actuation SMPS | F8: 5.0 | G8: Consumable | H8: Fuse - single-use protection element | I8: Badri | J8: India | K8: No | M8: In stock | N8: Mobile (travels with robot)
A9: 8 | B9: 10 | C9: Power & Switching | D9: 10-B Circuit Protection & IMD | E9: SPD - Surge Protection Device, VAL-SEC-T2-2+0-48DC-FM | F9: 1 | G9: Not consumable | H9: Durable equipment / spare component | I9: Badri | J9: India | K9: Yes | L9: PR-2026-1679 | M9: IQC Stage | N9: NY Stationary (stays in NY inventory)
A10: 9 | B10: 10 | C10: Power & Switching | D10: 10-B Circuit Protection & IMD | E10: IMD - AC Insulation Monitoring, ABB CM-IWS.1 | F10: 1 | G10: Not consumable | H10: Durable equipment / spare component | I10: Badri | J10: India | K10: Yes | L10: PR-2026-1680 | M10: IQC Stage | N10: Mobile (travels with robot)
A11: 10 | B11: 10 | C11: Power & Switching | D11: 10-C Contactors & SSRs | E11: SSR - SSR-50DD - planner logic | F11: 1 | G11: Not consumable | H11: Durable equipment / spare component | I11: Badri | J11: India | K11: No | M11: In stock | N11: Mobile (travels with robot)
A12: 11 | B12: 10 | C12: Power & Switching | D12: 10-C Contactors & SSRs | E12: SSR - SSR-10DD - OST safety | F12: 1 | G12: Not consumable | H12: Durable equipment / spare component | I12: Badri | J12: India | K12: No | M12: In stock | N12: NY Stationary (stays in NY inventory)
A13: 12 | B13: 10 | C13: Power & Switching | D13: 10-D Power Supplies & Converters | E13: Inverter - NTN-5K-248 CAN | F13: 1 | G13: Not consumable | H13: Durable equipment / spare component | I13: Badri | J13: India | K13: Yes | L13: PR-2026-1681 | M13: IQC Stage | N13: NY Stationary (stays in NY inventory)
A14: 13 | B14: 10 | C14: Power & Switching | D14: 10-D Power Supplies & Converters | E14: Buck Converter - DDR-240C-24 - control logic | F14: 1 | G14: Not consumable | H14: Durable equipment / spare component | I14: Badri | J14: India | K14: No | L14: PR-2026-1632 | M14: PR Raised | N14: Mobile (travels with robot)
A15: 14 | B15: 10 | C15: Power & Switching | D15: 10-D Power Supplies & Converters | E15: Buck Converter - DDR-480C-12 - planner logic | F15: 1 | G15: Not consumable | H15: Durable equipment / spare component | I15: Badri | J15: India | K15: No | M15: IQC Stage | N15: NY Stationary (stays in NY inventory)
A16: 15 | B16: 10 | C16: Power & Switching | D16: 10-D Power Supplies & Converters | E16: Trigger Board - USB Type-C PD HHM | F16: 2.0 | G16: Not consumable | H16: Durable equipment / spare component | I16: Uttez | J16: India | K16: No | L16: PR-2026-1501 | M16: In stock | N16: Mobile (travels with robot)
A17: 16 | B17: 10 | C17: Power & Switching | D17: 10-D Power Supplies & Converters | E17: Buck Converter - 5 V 3 A, AP66300 - PWM generation | F17: 1.0 | G17: Not consumable | H17: Durable equipment / spare component | I17: Uttez | J17: India | K17: No | M17: In stock | N17: Mobile (travels with robot)
A18: 17 | B18: 10 | C18: Power & Switching | D18: 10-D Power Supplies & Converters | E18: SMPS - 24 V, EDR-120-24 - TS sander actuators, TS sprayer actuators | F18: 1.0 | G18: Not consumable | H18: Durable equipment / spare component | I18: Uttez | J18: India | K18: Yes | L18: PR-2026-1626 | M18: In stock | N18: Mobile (travels with robot)
A19: 18 | B19: 10 | C19: Power & Switching | D19: 10-D Power Supplies & Converters | E19: SMPS-24V (110V AC input) | F19: 1.0 | G19: Not consumable | H19: Durable equipment / spare component | I19: Badri | J19: India | K19: No | M19: PR Raised
A20: 19 | B20: 10 | C20: Power & Switching | D20: 10-F Battery Chargers | E20: Power Bank - 25000 mAh 100 W, Stuffcool Giga Max - HHM | F20: 2.0 | G20: Not consumable | H20: Durable equipment / spare component | I20: Uttez | J20: India | K20: No | M20: Hold | N20: Mobile (travels with robot)
A21: 20 | B21: 10 | C21: Power & Switching | D21: 10-G E-Stops & Push Buttons | E21: E-Stop - Head, XB5AS8445 MoMa, OST | F21: 2.0 | G21: Not consumable | H21: Durable equipment / spare component | I21: Badri | J21: India | K21: No | L21: PR-2026-1613 | M21: PR Raised | N21: Mobile (travels with robot)
A22: 21 | B22: 10 | C22: Power & Switching | D22: 10-G E-Stops & Push Buttons | E22: E-Stop - NC Contact Block, ZBE-102N MoMa, OST | F22: 4.0 | G22: Not consumable | H22: Durable equipment / spare component | I22: Badri | J22: India | K22: Yes | L22: PR-2026-1682 | M22: In stock | N22: Mobile (travels with robot)
A23: 22 | B23: 10 | C23: Power & Switching | D23: 10-G E-Stops & Push Buttons | E23: Push Button - Red, XB5AA45 - TS sander sprayer | F23: 2 | G23: Not consumable | H23: Durable equipment / spare component | I23: Uttez | J23: India | K23: Yes | L23: PR-2026-1620 | M23: In stock | N23: Mobile (travels with robot)
A24: 23 | B24: 10 | C24: Power & Switching | D24: 10-G E-Stops & Push Buttons | E24: Push Button - Blue, XB5AA61 - TS sander sprayer | F24: 2.0 | G24: Not consumable | H24: Durable equipment / spare component | I24: Uttez | J24: India | K24: No | L24: PR-2026-1621 | M24: PR Raised | N24: Mobile (travels with robot)
A25: 24 | B25: 10 | C25: Power & Switching | D25: 10-G E-Stops & Push Buttons | E25: Push Button - Green, XB5AA31 - TS sander sprayer | F25: 2 | G25: Not consumable | H25: Durable equipment / spare component | I25: Uttez | J25: India | K25: Yes | L25: PR-2026-1622 | M25: In stock | N25: Mobile (travels with robot)
A26: 25 | B26: 10 | C26: Power & Switching | D26: 10-G E-Stops & Push Buttons | E26: Push Button - Yellow, XB5AA51 - TS sander sprayer | F26: 2 | G26: Not consumable | H26: Durable equipment / spare component | I26: Uttez | J26: India | K26: Yes | L26: PR-2026-1621 | M26: In stock | N26: Mobile (travels with robot)
A27: 26 | B27: 10 | C27: Power & Switching | D27: 10-H Switches | E27: Switch - Toggle, XB5AD21 - EM latch trigger | F27: 1 | G27: Not consumable | H27: Durable equipment / spare component | I27: Badri | J27: India | K27: No | M27: IQC Stage | N27: Mobile (travels with robot)
A28: 27 | B28: 10 | C28: Power & Switching | D28: 10-H Switches | E28: Switch - Power On, LAK39C-11T | F28: 1 | G28: Not consumable | H28: Durable equipment / spare component | I28: Badri | J28: India | K28: No | L28: PR-2026-1697 | M28: PR Raised | N28: Mobile (travels with robot)
A29: 28 | B29: 10 | C29: Power & Switching | D29: 10-H Switches | E29: Switch - Power with Integrated LED, LB12E-P10Z - HHM | F29: 1.0 | G29: Not consumable | H29: Durable equipment / spare component | I29: Uttez | J29: India | K29: No | M29: In stock | N29: Mobile (travels with robot)
A30: 29 | B30: 10 | C30: Power & Switching | D30: 10-I Indication Lights & LEDs | E30: Indication Light - 48 V DC, 3EPLBR348DC | F30: 1 | G30: Not consumable | H30: Durable equipment / spare component | I30: Badri | J30: India | K30: No | M30: IQC Stage | N30: NY Stationary (stays in NY inventory)
A31: 30 | B31: 10 | C31: Power & Switching | D31: 10-I Indication Lights & LEDs | E31: Indication Light - 24 V DC, 3EPLBR3L24DC Green MoMa, OST, TS Sander, TS Sprayer | F31: 5.0 | G31: Not consumable | H31: Durable equipment / spare component | I31: Badri | J31: India | K31: No | M31: In stock | N31: NY Stationary (stays in NY inventory)
A32: 31 | B32: 10 | C32: Power & Switching | D32: 10-I Indication Lights & LEDs | E32: Indication Light - 240 V AC, 3EPLBR5L240AC | F32: 1 | G32: Not consumable | H32: Durable equipment / spare component | I32: Badri | J32: India | K32: No | M32: IQC Stage | N32: NY Stationary (stays in NY inventory)
A33: 32 | B33: 10 | C33: Power & Switching | D33: 10-I Indication Lights & LEDs | E33: LED - Perception Light, CMB2550-57E-0A-N0B-00001 | F33: 7 | G33: Not consumable | H33: Durable equipment / spare component | I33: Badri | J33: India | K33: No | L33: PR-2026-1633 | M33: PR Raised | N33: Mobile (travels with robot)
A34: 33 | B34: 10 | C34: Power & Switching | D34: 10-I Indication Lights & LEDs | E34: Tower Light - 12 V, Q1-A | F34: 1 | G34: Not consumable | H34: Durable equipment / spare component | I34: Badri | J34: India | K34: Yes | L34: PR-2026-1698 | M34: PR Raised | N34: NY Stationary (stays in NY inventory)
A35: 34 | B35: 10 | C35: Power & Switching | D35: 10-I Indication Lights & LEDs | E35: Enclosure - Sander Latch Indication LED (3D printed) | F35: 1 | G35: Not consumable | H35: Durable equipment / spare component | I35: SANKALP | J35: India | K35: No | M35: To be Printed
A36: 35 | B36: 10 | C36: Power & Switching | D36: 10-I Indication Lights & LEDs | E36: LED - CREE XHP70D-00-0000-0D0BP450E - EOA LED Lights with PCBS | F36: 10.0 | G36: Not consumable | H36: Durable equipment / spare component | I36: Uttez | J36: India | K36: Yes | L36: PR-2026-1390 | M36: Payment Done | N36: Mobile (travels with robot)
A37: 36 | B37: 10 | C37: Power & Switching | D37: 10-I Indication Lights & LEDs | E37: LED - CREE XHP70D-00-0000-0D0BP450E EOA Light Set for Sander Vision | F37: 2.0 | G37: Not consumable | H37: Durable equipment / spare component | I37: Uttez | J37: India | K37: No | M37: To be Prepared | N37: Mobile (travels with robot)
A38: 37 | B38: 10 | C38: Power & Switching | D38: 10-I Indication Lights & LEDs | E38: LED - CREE XHP70D-00-0000-0D0BP450E EOA Light Set for Sprayer Vision | F38: 2.0 | G38: Not consumable | H38: Durable equipment / spare component | I38: Uttez | J38: India | K38: No | M38: In stock
A39: 38 | B39: 10 | C39: Power & Switching | D39: 10-I Indication Lights & LEDs | E39: Indicator LED - Red, 3PLBR4L-024 - TS comms / latch, sander & sprayer | F39: 4.0 | G39: Not consumable | H39: Durable equipment / spare component | I39: Uttez | J39: India | K39: Yes | L39: PR-2026-1618 | M39: In stock | N39: Mobile (travels with robot)
A40: 39 | B40: 10 | C40: Power & Switching | D40: 10-J Fans & Cooling | E40: Fan - Sunon 80 x 25 mm, 24 V DC - MoMa, OST, TS Sander | F40: 5.0 | G40: Not consumable | H40: Durable equipment / spare component | I40: Badri | J40: India | K40: No | L40: PR-2026-1659 | M40: PR Raised | N40: Mobile (travels with robot)
...

Sheet Summary
A1: Consumables classification - Packaging list V2 shipment
A2: 507 line items. "Consumable" = used up or destroyed in normal use and reordered on a cycle. "Borderline" = bulk stock or field-termination parts; classify to your own accounting rule. Basis for every line is on the Consumables Classification sheet. Procurement columns (Owner, Procure from, PR raised, PR number, Procurement status) are carried across unchanged from Sheet1 columns D, F, H, J and K.
A4: Overall
A5: Classification | B5: Line items
A6: Consumable | B6: =COUNTIF('Consumables Classification'!$G$2:$G$508,A6)
A7: Borderline | B7: =COUNTIF('Consumables Classification'!$G$2:$G$508,A7)
A8: Not consumable | B8: =COUNTIF('Consumables Classification'!$G$2:$G$508,A8)
A9: Total | B9: =SUM(B6:B8)
A11: Consumables by procurement status
A12: Procurement status | B12: Consumable | C12: Borderline | D12: Not consumable | E12: Total
A13: (blank) | B13: =COUNTIFS('Consumables Classification'!$M$2:$M$508,"",'Consumables Classification'!$G$2:$G$508,B$12) | C13: =COUNTIFS('Consumables Classification'!$M$2:$M$508,"",'Consumables Classification'!$G$2:$G$508,C$12) | D13: =COUNTIFS('Consumables Classification'!$M$2:$M$508,"",'Consumables Classification'!$G$2:$G$508,D$12) | E13: =SUM(B13:D13)
A14: Hold | B14: =COUNTIFS('Consumables Classification'!$M$2:$M$508,$A14,'Consumables Classification'!$G$2:$G$508,B$12) | C14: =COUNTIFS('Consumables Classification'!$M$2:$M$508,$A14,'Consumables Classification'!$G$2:$G$508,C$12) | D14: =COUNTIFS('Consumables Classification'!$M$2:$M$508,$A14,'Consumables Classification'!$G$2:$G$508,D$12) | E14: =SUM(B14:D14)
A15: IQC Stage | B15: =COUNTIFS('Consumables Classification'!$M$2:$M$508,$A15,'Consumables Classification'!$G$2:$G$508,B$12) | C15: =COUNTIFS('Consumables Classification'!$M$2:$M$508,$A15,'Consumables Classification'!$G$2:$G$508,C$12) | D15: =COUNTIFS('Consumables Classification'!$M$2:$M$508,$A15,'Consumables Classification'!$G$2:$G$508,D$12) | E15: =SUM(B15:D15)
A16: In stock | B16: =COUNTIFS('Consumables Classification'!$M$2:$M$508,$A16,'Consumables Classification'!$G$2:$G$508,B$12) | C16: =COUNTIFS('Consumables Classification'!$M$2:$M$508,$A16,'Consumables Classification'!$G$2:$G$508,C$12) | D16: =COUNTIFS('Consumables Classification'!$M$2:$M$508,$A16,'Consumables Classification'!$G$2:$G$508,D$12) | E16: =SUM(B16:D16)
A17: PR Raised | B17: =COUNTIFS('Consumables Classification'!$M$2:$M$508,$A17,'Consumables Classification'!$G$2:$G$508,B$12) | C17: =COUNTIFS('Consumables Classification'!$M$2:$M$508,$A17,'Consumables Classification'!$G$2:$G$508,C$12) | D17: =COUNTIFS('Consumables Classification'!$M$2:$M$508,$A17,'Consumables Classification'!$G$2:$G$508,D$12) | E17: =SUM(B17:D17)
A18: Payment Done | B18: =COUNTIFS('Consumables Classification'!$M$2:$M$508,$A18,'Consumables Classification'!$G$2:$G$508,B$12) | C18: =COUNTIFS('Consumables Classification'!$M$2:$M$508,$A18,'Consumables Classification'!$G$2:$G$508,C$12) | D18: =COUNTIFS('Consumables Classification'!$M$2:$M$508,$A18,'Consumables Classification'!$G$2:$G$508,D$12) | E18: =SUM(B18:D18)
A19: To be Prepared | B19: =COUNTIFS('Consumables Classification'!$M$2:$M$508,$A19,'Consumables Classification'!$G$2:$G$508,B$12) | C19: =COUNTIFS('Consumables Classification'!$M$2:$M$508,$A19,'Consumables Classification'!$G$2:$G$508,C$12) | D19: =COUNTIFS('Consumables Classification'!$M$2:$M$508,$A19,'Consumables Classification'!$G$2:$G$508,D$12) | E19: =SUM(B19:D19)
A20: To be Printed | B20: =COUNTIFS('Consumables Classification'!$M$2:$M$508,$A20,'Consumables Classification'!$G$2:$G$508,B$12) | C20: =COUNTIFS('Consumables Classification'!$M$2:$M$508,$A20,'Consumables Classification'!$G$2:$G$508,C$12) | D20: =COUNTIFS('Consumables Classification'!$M$2:$M$508,$A20,'Consumables Classification'!$G$2:$G$508,D$12) | E20: =SUM(B20:D20)
A21: To be purchased | B21: =COUNTIFS('Consumables Classification'!$M$2:$M$508,$A21,'Consumables Classification'!$G$2:$G$508,B$12) | C21: =COUNTIFS('Consumables Classification'!$M$2:$M$508,$A21,'Consumables Classification'!$G$2:$G$508,C$12) | D21: =COUNTIFS('Consumables Classification'!$M$2:$M$508,$A21,'Consumables Classification'!$G$2:$G$508,D$12) | E21: =SUM(B21:D21)
A22: Total | B22: =SUM(B13:B21) | C22: =SUM(C13:C21) | D22: =SUM(D13:D21) | E22: =SUM(E13:E21)
A24: Consumables by procurement source
A25: Procure from | B25: Consumable | C25: Borderline | D25: Not consumable | E25: Total
A26: India | B26: =COUNTIFS('Consumables Classification'!$J$2:$J$508,$A26,'Consumables Classification'!$G$2:$G$508,B$25) | C26: =COUNTIFS('Consumables Classification'!$J$2:$J$508,$A26,'Consumables Classification'!$G$2:$G$508,C$25) | D26: =COUNTIFS('Consumables Classification'!$J$2:$J$508,$A26,'Consumables Classification'!$G$2:$G$508,D$25) | E26: =SUM(B26:D26)
A27: Buy in US | B27: =COUNTIFS('Consumables Classification'!$J$2:$J$508,$A27,'Consumables Classification'!$G$2:$G$508,B$25) | C27: =COUNTIFS('Consumables Classification'!$J$2:$J$508,$A27,'Consumables Classification'!$G$2:$G$508,C$25) | D27: =COUNTIFS('Consumables Classification'!$J$2:$J$508,$A27,'Consumables Classification'!$G$2:$G$508,D$25) | E27: =SUM(B27:D27)
A30: By box
A31: Box | B31: Box category | C31: Consumable | D31: Borderline | E31: Not consumable | F31: Total
A32: 1 | B32: MoMa | C32: =COUNTIFS('Consumables Classification'!$B$2:$B$508,1,'Consumables Classification'!$C$2:$C$508,$B32,'Consumables Classification'!$G$2:$G$508,C$31) | D32: =COUNTIFS('Consumables Classification'!$B$2:$B$508,1,'Consumables Classification'!$C$2:$C$508,$B32,'Consumables Classification'!$G$2:$G$508,D$31) | E32: =COUNTIFS('Consumables Classification'!$B$2:$B$508,1,'Consumables Classification'!$C$2:$C$508,$B32,'Consumables Classification'!$G$2:$G$508,E$31) | F32: =SUM(C32:E32)
A33: 2 | B33: Bringup Kit | C33: =COUNTIFS('Consumables Classification'!$B$2:$B$508,2,'Consumables Classification'!$C$2:$C$508,$B33,'Consumables Classification'!$G$2:$G$508,C$31) | D33: =COUNTIFS('Consumables Classification'!$B$2:$B$508,2,'Consumables Classification'!$C$2:$C$508,$B33,'Consumables Classification'!$G$2:$G$508,D$31) | E33: =COUNTIFS('Consumables Classification'!$B$2:$B$508,2,'Consumables Classification'!$C$2:$C$508,$B33,'Consumables Classification'!$G$2:$G$508,E$31) | F33: =SUM(C33:E33)
A34: 3 | B34: UR Arm | C34: =COUNTIFS('Consumables Classification'!$B$2:$B$508,3,'Consumables Classification'!$C$2:$C$508,$B34,'Consumables Classification'!$G$2:$G$508,C$31) | D34: =COUNTIFS('Consumables Classification'!$B$2:$B$508,3,'Consumables Classification'!$C$2:$C$508,$B34,'Consumables Classification'!$G$2:$G$508,D$31) | E34: =COUNTIFS('Consumables Classification'!$B$2:$B$508,3,'Consumables Classification'!$C$2:$C$508,$B34,'Consumables Classification'!$G$2:$G$508,E$31) | F34: =SUM(C34:E34)
A35: 6 | B35: Tool Sprayer System | C35: =COUNTIFS('Consumables Classification'!$B$2:$B$508,6,'Consumables Classification'!$C$2:$C$508,$B35,'Consumables Classification'!$G$2:$G$508,C$31) | D35: =COUNTIFS('Consumables Classification'!$B$2:$B$508,6,'Consumables Classification'!$C$2:$C$508,$B35,'Consumables Classification'!$G$2:$G$508,D$31) | E35: =COUNTIFS('Consumables Classification'!$B$2:$B$508,6,'Consumables Classification'!$C$2:$C$508,$B35,'Consumables Classification'!$G$2:$G$508,E$31) | F35: =SUM(C35:E35)
A36: 7 | B36: Tool Sprayer Station | C36: =COUNTIFS('Consumables Classification'!$B$2:$B$508,7,'Consumables Classification'!$C$2:$C$508,$B36,'Consumables Classification'!$G$2:$G$508,C$31) | D36: =COUNTIFS('Consumables Classification'!$B$2:$B$508,7,'Consumables Classification'!$C$2:$C$508,$B36,'Consumables Classification'!$G$2:$G$508,D$31) | E36: =COUNTIFS('Consumables Classification'!$B$2:$B$508,7,'Consumables Classification'!$C$2:$C$508,$B36,'Consumables Classification'!$G$2:$G$508,E$31) | F36: =SUM(C36:E36)
A37: 8 | B37: Accessories (OST & HHM) | C37: =COUNTIFS('Consumables Classification'!$B$2:$B$508,8,'Consumables Classification'!$C$2:$C$508,$B37,'Consumables Classification'!$G$2:$G$508,C$31) | D37: =COUNTIFS('Consumables Classification'!$B$2:$B$508,8,'Consumables Classification'!$C$2:$C$508,$B37,'Consumables Classification'!$G$2:$G$508,D$31) | E37: =COUNTIFS('Consumables Classification'!$B$2:$B$508,8,'Consumables Classification'!$C$2:$C$508,$B37,'Consumables Classification'!$G$2:$G$508,E$31) | F37: =SUM(C37:E37)
A38: 9 | B38: Compute & Network | C38: =COUNTIFS('Consumables Classification'!$B$2:$B$508,9,'Consumables Classification'!$C$2:$C$508,$B38,'Consumables Classification'!$G$2:$G$508,C$31) | D38: =COUNTIFS('Consumables Classification'!$B$2:$B$508,9,'Consumables Classification'!$C$2:$C$508,$B38,'Consumables Classification'!$G$2:$G$508,D$31) | E38: =COUNTIFS('Consumables Classification'!$B$2:$B$508,9,'Consumables Classification'!$C$2:$C$508,$B38,'Consumables Classification'!$G$2:$G$508,E$31) | F38: =SUM(C38:E38)
A39: 9 | B39: Mechanical parts | C39: =COUNTIFS('Consumables Classification'!$B$2:$B$508,9,'Consumables Classification'!$C$2:$C$508,$B39,'Consumables Classification'!$G$2:$G$508,C$31) | D39: =COUNTIFS('Consumables Classification'!$B$2:$B$508,9,'Consumables Classification'!$C$2:$C$508,$B39,'Consumables Classification'!$G$2:$G$508,D$31) | E39: =COUNTIFS('Consumables Classification'!$B$2:$B$508,9,'Consumables Classification'!$C$2:$C$508,$B39,'Consumables Classification'!$G$2:$G$508,E$31) | F39: =SUM(C39:E39)
A40: 10 | B40: Power & Switching | C40: =COUNTIFS('Consumables Classification'!$B$2:$B$508,10,'Consumables Classification'!$C$2:$C$508,$B40,'Consumables Classification'!$G$2:$G$508,C$31) | D40: =COUNTIFS('Consumables Classification'!$B$2:$B$508,10,'Consumables Classification'!$C$2:$C$508,$B40,'Consumables Classification'!$G$2:$G$508,D$31) | E40: =COUNTIFS('Consumables Classification'!$B$2:$B$508,10,'Consumables Classification'!$C$2:$C$508,$B40,'Consumables Classification'!$G$2:$G$508,E$31) | F40: =SUM(C40:E40)
A41: 11 | B41: Sensors | C41: =COUNTIFS('Consumables Classification'!$B$2:$B$508,11,'Consumables Classification'!$C$2:$C$508,$B41,'Consumables Classification'!$G$2:$G$508,C$31) | D41: =COUNTIFS('Consumables Classification'!$B$2:$B$508,11,'Consumables Classification'!$C$2:$C$508,$B41,'Consumables Classification'!$G$2:$G$508,D$31) | E41: =COUNTIFS('Consumables Classification'!$B$2:$B$508,11,'Consumables Classification'!$C$2:$C$508,$B41,'Consumables Classification'!$G$2:$G$508,E$31) | F41: =SUM(C41:E41)
A42: 12 | B42: Actuators | C42: =COUNTIFS('Consumables Classification'!$B$2:$B$508,12,'Consumables Classification'!$C$2:$C$508,$B42,'Consumables Classification'!$G$2:$G$508,C$31) | D42: =COUNTIFS('Consumables Classification'!$B$2:$B$508,12,'Consumables Classification'!$C$2:$C$508,$B42,'Consumables Classification'!$G$2:$G$508,D$31) | E42: =COUNTIFS('Consumables Classification'!$B$2:$B$508,12,'Consumables Classification'!$C$2:$C$508,$B42,'Consumables Classification'!$G$2:$G$508,E$31) | F42: =SUM(C42:E42)
A43: 13 | B43: Diagnostic & repair tools | C43: =COUNTIFS('Consumables Classification'!$B$2:$B$508,13,'Consumables Classification'!$C$2:$C$508,$B43,'Consumables Classification'!$G$2:$G$508,C$31) | D43: =COUNTIFS('Consumables Classification'!$B$2:$B$508,13,'Consumables Classification'!$C$2:$C$508,$B43,'Consumables Classification'!$G$2:$G$508,D$31) | E43: =COUNTIFS('Consumables Classification'!$B$2:$B$508,13,'Consumables Classification'!$C$2:$C$508,$B43,'Consumables Classification'!$G$2:$G$508,E$31) | F43: =SUM(C43:E43)
A44: 13 | B44: Wire, connector, cables & crimps | C44: =COUNTIFS('Consumables Classification'!$B$2:$B$508,13,'Consumables Classification'!$C$2:$C$508,$B44,'Consumables Classification'!$G$2:$G$508,C$31) | D44: =COUNTIFS('Consumables Classification'!$B$2:$B$508,13,'Consumables Classification'!$C$2:$C$508,$B44,'Consumables Classification'!$G$2:$G$508,D$31) | E44: =COUNTIFS('Consumables Classification'!$B$2:$B$508,13,'Consumables Classification'!$C$2:$C$508,$B44,'Consumables Classification'!$G$2:$G$508,E$31) | F44: =SUM(C44:E44)
A45: 14 | B45: Custom PCB | C45: =COUNTIFS('Consumables Classification'!$B$2:$B$508,14,'Consumables Classification'!$C$2:$C$508,$B45,'Consumables Classification'!$G$2:$G$508,C$31) | D45: =COUNTIFS('Consumables Classification'!$B$2:$B$508,14,'Consumables Classification'!$C$2:$C$508,$B45,'Consumables Classification'!$G$2:$G$508,D$31) | E45: =COUNTIFS('Consumables Classification'!$B$2:$B$508,14,'Consumables Classification'!$C$2:$C$508,$B45,'Consumables Classification'!$G$2:$G$508,E$31) | F45: =SUM(C45:E45)
...

Sheet Consumables to procure
A1: Consumable + borderline items not yet in stock
A2: Everything classified consumable or borderline whose procurement status is not "In stock". Sorted by status, then box.
A4: Row in Sheet1 | B4: Box | C4: Item | D4: Qty | E4: Classification | F4: Owner | G4: Procure from | H4: PR number | I4: Procurement status
A5: 400 | B5: 17 | C5: PPE - Rubber Boots | D5: 1 | E5: Borderline | F5: Kaustubh | G5: India | I5: Hold
A6: 434 | B6: 18 | C6: Filter - Sander Vacuum, 8999600411 | D6: 1 | E6: Consumable | F6: SANKALP | G6: Buy in US | I6: Hold
A7: 445 | B7: 19 | C7: Foam - EPE Sheet | D7: 25 | E7: Consumable | F7: Kaustubh | G7: India | I7: Hold
A8: 446 | B8: 19 | C8: Bubble Wrap - Roll, 1 m wide | D8: 1 roll | E8: Consumable | F8: Kaustubh | G8: India | I8: Hold
A9: 447 | B9: 19 | C9: Stretch Film - Polyethylene Wrap, 500 mm | D9: 3 rolls | E9: Consumable | F9: Kaustubh | G9: India | I9: Hold
A10: 452 | B10: 19 | C10: Paint - Spray, Matt Black | D10: 2 | E10: Consumable | F10: Kaustubh | G10: Buy in US | I10: Hold
A11: 453 | B11: 19 | C11: Paint - Spray, Red | D11: 2 | E11: Consumable | F11: Kaustubh | G11: Buy in US | I11: Hold
A12: 203 | B12: 2 | C12: Battery - Li-SOCl2 AA, ER14505 - driver encoder (Spare) | D12: 4.0 | E12: Consumable | F12: Badri | G12: India | I12: IQC Stage
A13: 463 | B13: 2 | C13: Bolt - Socket Cap (SHCS), M5 x 16 mm - EOA quick-lock fastener | D13: 6 | E13: Consumable | F13: Kaustubh | G13: India | I13: IQC Stage
A14: 464 | B14: 2 | C14: Bolt - Socket Cap (SHCS), M8 x 50 mm - arm mounting | D14: 4 | E14: Consumable | F14: Kaustubh | G14: India | I14: IQC Stage
A15: 465 | B15: 2 | C15: Bolt - Socket Cap (SHCS), M8 x 40 mm - arm mounting | D15: 4 | E15: Consumable | F15: Kaustubh | G15: India | I15: IQC Stage
A16: 466 | B16: 2 | C16: Nut - Nylon Lock, M8 - arm mounting | D16: 4 | E16: Consumable | F16: Kaustubh | G16: India | I16: IQC Stage
... A21: 451 | B21: 19 | C21: Label - Shipping Labels & Stamps | D21: 6 | E21: Consumable | F21: Kaustubh | G21: India | I21: IQC Stage
A22: 457 | B22: 2 | C22: Knife Blades | D22: 1 | E22: Consumable | F22: Kaustubh | G22: India | H22: PR-2026-1651 | I22: PR Raised
A23: 110 | B23: 12 | C23: Bolt - Countersunk (CSK), M6 x 15 mm - piston rod end | D23: 8 | E23: Consumable | F23: Anand | G23: India | H23: PR-2026-1564 | I23: PR Raised
A24: 123 | B24: 13 | C24: Wire - PVC, 24 AWG, 2 Core | D24: 10 | E24: Borderline | F24: Badri | G24: India | I24: PR Raised
A25: 150 | B25: 13 | C25: Crimp - JST XA Female (SXA-001T-P0.6) | D25: 200.0 | E25: Consumable | F25: Badri | G25: India | I25: PR Raised
A26: 167 | B26: 13 | C26: Connector - RJ45 Cat 6, CE6324 | D26: 20 | E26: Borderline | F26: Badri | G26: India | I26: PR Raised
A27: 168 | B27: 13 | C27: Boot Cap - RJ45, CE6324 | D27: 20 | E27: Borderline | F27: Badri | G27: India | I27: PR Raised
A28: 169 | B28: 13 | C28: Connector - RJ45 Cat 7, FEDUS-CAT7 | D28: 20 | E28: Borderline | F28: Badri | G28: India | I28: PR Raised
A29: 196 | B29: 13 | C29: Lug - Ring, 4 AWG, M8 stud | D29: 30 | E29: Consumable | F29: Badri | G29: India | I29: PR Raised
A30: 197 | B30: 13 | C30: Lug - Ring, 6 AWG, M8 stud | D30: 30 | E30: Consumable | F30: Badri | G30: India | I30: PR Raised
A31: 198 | B31: 13 | C31: Lug - Ring, 12 AWG, M8 stud | D31: 20 | E31: Consumable | F31: Badri | G31: India | I31: PR Raised
A32: 199 | B32: 13 | C32: Lug - Ring, 14 AWG, M8 stud | D32: 20 | E32: Consumable | F32: Badri | G32: India | I32: PR Raised
A33: 200 | B33: 13 | C33: Lug - Ring, 14 AWG, M6 stud | D33: 20 | E33: Consumable | F33: Badri | G33: India | I33: PR Raised
A34: 201 | B34: 13 | C34: Lug - Ring, 22 AWG, M8 stud | D34: 20 | E34: Consumable | F34: Badri | G34: India | I34: PR Raised
A35: 202 | B35: 13 | C35: Lug - Ring, 22 AWG, M3 stud | D35: 20 | E35: Consumable | F35: Badri | G35: India | I35: PR Raised
A36: 204 | B36: 13 | C36: Lug - Ring, 22 AWG, M6 stud | D36: 20 | E36: Consumable | F36: Badri | G36: India | I36: PR Raised
A37: 211 | B37: 13 | C37: Conduit- Cable, PG7 | D37: 3m | E37: Borderline | F37: Kaustubh | G37: India | H37: PR-2026-1650 | I37: PR Raised
A38: 212 | B38: 13 | C38: Conduit- Cable, PG9 | D38: 3m | E38: Borderline | F38: Kaustubh | G38: India | H38: PR-2026-1650 | I38: PR Raised
A39: 213 | B39: 13 | C39: Conduit - Cable, PG11 | D39: 3m | E39: Borderline | F39: Kaustubh | G39: India | H39: PR-2026-1650 | I39: PR Raised
A40: 214 | B40: 13 | C40: Cable Track - 15 x 30 mm | D40: 2m | E40: Borderline | F40: SANKALP | G40: India | H40: PR-2026-1642 | I40: PR Raised
A41: 335 | B41: 16 | C41: Nut - Nylon Lock, M4 | D41: 20.0 | E41: Consumable | F41: Kaustubh | G41: India | H41: PR-2026-1677 | I41: PR Raised
A42: 340 | B42: 16 | C42: Washer - Flat, M2 | D42: 20.0 | E42: Consumable | F42: Kaustubh | G42: India | H42: PR-2026-1677 | I42: PR Raised
A43: 343 | B43: 16 | C43: Washer - Flat, M5 | D43: 20.0 | E43: Consumable | F43: Kaustubh | G43: India | H43: PR-2026-1677 | I43: PR Raised
A44: 344 | B44: 16 | C44: Washer - Flat, M6 | D44: 20.0 | E44: Consumable | F44: Kaustubh | G44: India | H44: PR-2026-1677 | I44: PR Raised
A45: 350 | B45: 16 | C45: Washer - Spring, M4 | D45: 20.0 | E45: Consumable | F45: Kaustubh | G45: India | H45: PR-2026-1677 | I45: PR Raised
...

Sheet Flags
A1: Things to fix or confirm in the packing list
A3: Row in Sheet1 | B3: Item | C3: Issue
A4: 134 | B4: . | C4: Item name is a single "." with qty 2 - blank line item, needs a real description.
A5: 504 | B5: Compound Plus 3 - 4.5 gallon bucket | C5: Consumable with no box number assigned (NYC Site & Facility).
A6: 505 | B6: No Pock Pro Warner Tools | C6: Consumable with no box number assigned.
A7: 506 | B7: Distilled Water | C7: Consumable with no box number assigned.
A8: 507 | B8: 1litre measuring beaker | C8: No box number assigned; not a consumable (reusable vessel).
A9: 431 | B9: Diffuser Sheets | C9: Filed in Box 18 Consumables but is an optical part. Duplicates row 374 "Sheet - Light Diffuser" in Box 16.
A10: 483 | B10: Threadlocker - Loctite 243 | C10: Consumable chemical held in Box 2 Bringup Kit, separate from the Box 18 threadlocker (Loctite 271, row 418).
A11: 457 | B11: Knife Blades | C11: Consumable blades filed under Box 2 Hand Tools, not Box 18 Abrasives & Blades.
A12: 389 | B12: Caulking Gun Nozzle | C12: Consumable nozzle filed under Box 17 Hand Tools.
A13: 203 | B13: Battery - Li-SOCl2 AA ER14505 (Spare) | C13: Duplicate of row 472, same part, both Box 2. Confirm whether 4 or 8 cells ship.
A14: 471 | B14: SSD - External SanDisk 4 TB | C14: Duplicate of row 487 (Box 9). Confirm quantity.
A15: 180 | B15: Cable - USB C to USB C | C15: Duplicate of row 126. Confirm quantity.
... A20: 358 | B20: Mount - Drag Chain, Front | C20: Qty blank.

Sheet Hazmat watchlist
A1: Consumables that are regulated for air / ocean freight
A2: Flagged from item descriptions only - confirm each against the supplier SDS and your forwarder before booking.
A4: Row in Sheet1 | B4: Item | C4: Why it is regulated
A5: 424 | B5: Chemical - Isopropyl Alcohol (IPA) | C5: Flammable liquid, UN1219 class 3.
A6: 425 | B6: Paint - Spray, General Purpose (qty 2) | C6: Aerosol, class 2.1.
A7: 452 | B7: Paint - Spray, Matt Black (qty 2) | C7: Aerosol, class 2.1.
A8: 453 | B8: Paint - Spray, Red (qty 2) | C8: Aerosol, class 2.1.
A9: 415 | B9: Adhesive - Cyanoacrylate, Metloc 743 | C9: Adhesive - check SDS, often restricted by quantity.
A10: 413 | B10: Sealant - Polyurethane, Sika Sikaflex-221 | C10: Adhesive/sealant - check SDS.
A11: 417 | B11: Adhesive - Epoxy, Araldite | C11: Resin/hardener - check SDS.
A12: 418 | B12: Threadlocker - Loctite 271, 250 ml | C12: Anaerobic adhesive - check SDS.
A13: 483 | B13: Threadlocker - Loctite 243 | C13: Anaerobic adhesive - check SDS.
A14: 426 | B14: Lubricant - Tapping Oil | C14: Oil - check flash point on SDS.
A15: 427 | B15: Lubricant - Cutting Oil | C15: Oil - check flash point on SDS.
A16: 203 | B16: Battery - Li-SOCl2 AA, ER14505 (spare) | C16: Lithium metal cell, UN3090/3091 - shipping paperwork required.
... A18: 19 | B18: Power Bank - 25000 mAh 100 W (qty 2) | C18: Lithium-ion ~92.5 Wh each - passenger baggage only, never freight. Sheet1 already notes "Luggage Item".

Sheet Sheet1
A1: Power & Switching | B1: Fuse - ANM 250 A / 70 V (ANM70V-250A) - robot main | C1: 10-A Fuses | D1: Badri | E1: 3 | F1: India | H1: No | K1: In stock | L1: 10 | M1: FALSE | N1: 5 | S1: Mobile (travels with robot) | U1: 40 | V1: =IF($K1="To be purchased",COUNTIF($K1:$K$2,"To be purchased"),"")
A2: Power & Switching | B2: Fuse - ATN 20 A - travel motor, UR Controller, Planner Actuation, Planner Logic Buck | C2: 10-A Fuses | D2: Badri | E2: 10 | F2: India | H2: No | K2: In stock | L2: 10 | M2: FALSE | N2: 5 | S2: Mobile (travels with robot) | U2: 56 | V2: =IF($K2="To be purchased",COUNTIF($K2:$K$2,"To be purchased"),"")
A3: Power & Switching | B3: Fuse - ATN 10 A - steering motor | C3: 10-A Fuses | D3: Badri | E3: 6 | F3: India | H3: No | K3: In stock | L3: 10 | M3: FALSE | N3: 5 | S3: Mobile (travels with robot) | U3: 57 | V3: =IF($K3="To be purchased",COUNTIF($K3:$K$2,"To be purchased"),"")
A4: Power & Switching | B4: Fuse - ATM 40 A - lift kit | C4: 10-A Fuses | D4: Badri | E4: 2 | F4: India | H4: No | K4: In stock | L4: 10 | M4: FALSE | N4: 5 | S4: Mobile (travels with robot) | U4: 60 | V4: =IF($K4="To be purchased",COUNTIF($K4:$K$2,"To be purchased"),"")
A5: Power & Switching | B5: Fuse - ATN 15 A - control logic buck | C5: 10-A Fuses | D5: Badri | E5: 2 | F5: India | H5: No | K5: In stock | L5: 10 | M5: FALSE | N5: 5 | S5: NY Stationary (stays in NY inventory) | U5: 76 | V5: =IF($K5="To be purchased",COUNTIF($K5:$K$2,"To be purchased"),"")
A6: Power & Switching | B6: Fuse - ANM 125 A / 70 V (ANM70V-125A) - OST main | C6: 10-A Fuses | D6: Badri | E6: 2 | F6: India | H6: No | K6: In stock | L6: 10 | M6: FALSE | N6: 5 | S6: Mobile (travels with robot) | U6: 120 | V6: =IF($K6="To be purchased",COUNTIF($K6:$K$2,"To be purchased"),"")
A7: Power & Switching | B7: Fuse - Blade Mini 5 A - OST logic, TS sander actuation SMPS, TS sprayer actuation SMPS | C7: 10-A Fuses | D7: Badri | E7: 5 | F7: India | H7: No | K7: In stock | L7: 10 | M7: FALSE | N7: 5 | S7: Mobile (travels with robot) | U7: 123 | V7: =IF($K7="To be purchased",COUNTIF($K7:$K$2,"To be purchased"),"")
A8: Power & Switching | B8: SPD - Surge Protection Device, VAL-SEC-T2-2+0-48DC-FM | C8: 10-B Circuit Protection & IMD | D8: Badri | E8: 1 | F8: India | H8: Yes | J8: =IFERROR(HYPERLINK("https://docs.google.com/spreadsheets/d/10M8oEMfSST-xuPwcSARfQDNcQJ0xrCp8O9iHBGPAr34/edit?gid=1956219685&range=A"&MATCH("PR-2026-1679",'PR Lookup'!A:A,0),"PR-2026-1679"),"PR-2026-1679") | K8: IQC Stage | L8: 10 | M8: FALSE | N8: 5 | S8: NY Stationary (stays in NY inventory) | U8: 45 | V8: =IF($K8="To be purchased",COUNTIF($K8:$K$2,"To be purchased"),"")
A9: Power & Switching | B9: IMD - AC Insulation Monitoring, ABB CM-IWS.1 | C9: 10-B Circuit Protection & IMD | D9: Badri | E9: 1 | F9: India | H9: Yes | J9: =IFERROR(HYPERLINK("https://docs.google.com/spreadsheets/d/10M8oEMfSST-xuPwcSARfQDNcQJ0xrCp8O9iHBGPAr34/edit?gid=1956219685&range=A"&MATCH("PR-2026-1680",'PR Lookup'!A:A,0),"PR-2026-1680"),"PR-2026-1680") | K9: IQC Stage | L9: 10 | M9: FALSE | N9: 5 | S9: Mobile (travels with robot) | U9: 55 | V9: =IF($K9="To be purchased",COUNTIF($K9:$K$2,"To be purchased"),"")
A10: Power & Switching | B10: SSR - SSR-50DD - planner logic | C10: 10-C Contactors & SSRs | D10: Badri | E10: 1 | F10: India | H10: No | K10: In stock | L10: 10 | M10: FALSE | N10: 5 | S10: Mobile (travels with robot) | U10: 78 | V10: =IF($K10="To be purchased",COUNTIF($K10:$K$2,"To be purchased"),"")
A11: Power & Switching | B11: SSR - SSR-10DD - OST safety | C11: 10-C Contactors & SSRs | D11: Badri | E11: 1 | F11: India | H11: No | K11: In stock | L11: 10 | M11: FALSE | N11: 5 | S11: NY Stationary (stays in NY inventory) | U11: 125 | V11: =IF($K11="To be purchased",COUNTIF($K11:$K$2,"To be purchased"),"")
A12: Power & Switching | B12: Inverter - NTN-5K-248 CAN | C12: 10-D Power Supplies & Converters | D12: Badri | E12: 1 | F12: India | H12: Yes | J12: =IFERROR(HYPERLINK("https://docs.google.com/spreadsheets/d/10M8oEMfSST-xuPwcSARfQDNcQJ0xrCp8O9iHBGPAr34/edit?gid=1956219685&range=A"&MATCH("PR-2026-1681",'PR Lookup'!A:A,0),"PR-2026-1681"),"PR-2026-1681") | K12: IQC Stage | L12: 10 | M12: FALSE | N12: 5 | S12: NY Stationary (stays in NY inventory) | U12: 50 | V12: =IF($K12="To be purchased",COUNTIF($K12:$K$2,"To be purchased"),"")
A13: Power & Switching | B13: Buck Converter - DDR-240C-24 - control logic | C13: 10-D Power Supplies & Converters | D13: Badri | E13: 1 | F13: India | H13: No | J13: =IFERROR(HYPERLINK("https://docs.google.com/spreadsheets/d/10M8oEMfSST-xuPwcSARfQDNcQJ0xrCp8O9iHBGPAr34/edit?gid=1956219685&range=A"&MATCH("PR-2026-1632",'PR Lookup'!A:A,0),"PR-2026-1632"),"PR-2026-1632") | K13: PR Raised | L13: 10 | M13: FALSE | N13: 5 | S13: Mobile (travels with robot) | U13: 75 | V13: =IF($K13="To be purchased",COUNTIF($K13:$K$2,"To be purchased"),"")
A14: Power & Switching | B14: Buck Converter - DDR-480C-12 - planner logic | C14: 10-D Power Supplies & Converters | D14: Badri | E14: 1 | F14: India | H14: No | K14: IQC Stage | L14: 10 | M14: FALSE | N14: 5 | S14: NY Stationary (stays in NY inventory) | U14: 92 | V14: =IF($K14="To be purchased",COUNTIF($K14:$K$2,"To be purchased"),"")
A15: Power & Switching | B15: Trigger Board - USB Type-C PD HHM | C15: 10-D Power Supplies & Converters | D15: Uttez | E15: 2 | F15: India | H15: No | J15: =IFERROR(HYPERLINK("https://docs.google.com/spreadsheets/d/10M8oEMfSST-xuPwcSARfQDNcQJ0xrCp8O9iHBGPAr34/edit?gid=1956219685&range=A"&MATCH("PR-2026-1501",'PR Lookup'!A:A,0),"PR-2026-1501"),"PR-2026-1501") | K15: In stock | L15: 10 | M15: FALSE | N15: 5 | S15: Mobile (travels with robot) | U15: 153 | V15: =IF($K15="To be purchased",COUNTIF($K15:$K$2,"To be purchased"),"")
A16: Power & Switching | B16: Buck Converter - 5 V 3 A, AP66300 - PWM generation | C16: 10-D Power Supplies & Converters | D16: Uttez | E16: 1 | F16: India | H16: No | K16: In stock | L16: 10 | M16: FALSE | N16: 5 | S16: Mobile (travels with robot) | U16: 447 | V16: =IF($K16="To be purchased",COUNTIF($K16:$K$2,"To be purchased"),"")
A17: Power & Switching | B17: SMPS - 24 V, EDR-120-24 - TS sander actuators, TS sprayer actuators | C17: 10-D Power Supplies & Converters | D17: Uttez | E17: 1 | F17: India | H17: Yes | J17: =IFERROR(HYPERLINK("https://docs.google.com/spreadsheets/d/10M8oEMfSST-xuPwcSARfQDNcQJ0xrCp8O9iHBGPAr34/edit?gid=1956219685&range=A"&MATCH("PR-2026-1626",'PR Lookup'!A:A,0),"PR-2026-1626"),"PR-2026-1626") | K17: In stock | L17: 10 | M17: FALSE | N17: 5 | P17: IQC : Input 220V AC Output 24V DC | S17: Mobile (travels with robot) | T17: Also stocked in: Tool Spares / Sprayer EBOM. Kept separate on purpose - one per box. | U17: 488 | V17: =IF($K17="To be purchased",COUNTIF($K17:$K$2,"To be purchased"),"")
A18: Power & Switching | B18: SMPS-24V (110V AC input) | C18: 10-D Power Supplies & Converters | D18: Badri | E18: 1 | F18: India | H18: No | K18: PR Raised | L18: 10 | M18: FALSE | N18: 5
A19: Power & Switching | B19: Power Bank - 25000 mAh 100 W, Stuffcool Giga Max - HHM | C19: 10-F Battery Chargers | D19: Uttez | E19: 2 | F19: India | H19: No | K19: Hold | L19: 10 | M19: FALSE | N19: 5 | P19: Luggage Item, Not a Spare Item | S19: Mobile (travels with robot) | T19: [BOX NAME CORRECTED: was "Luggage"] | U19: 137 | V19: =IF($K19="To be purchased",COUNTIF($K$2:$K19,"To be purchased"),"")
A20: Power & Switching | B20: E-Stop - Head, XB5AS8445 MoMa, OST | C20: 10-G E-Stops & Push Buttons | D20: Badri | E20: 2 | F20: India | H20: No | J20: =IFERROR(HYPERLINK("https://docs.google.com/spreadsheets/d/10M8oEMfSST-xuPwcSARfQDNcQJ0xrCp8O9iHBGPAr34/edit?gid=1956219685&range=A"&MATCH("PR-2026-1613",'PR Lookup'!A:A,0),"PR-2026-1613"),"PR-2026-1613") | K20: PR Raised | L20: 10 | M20: FALSE | N20: 5 | S20: Mobile (travels with robot) | U20: 51 | V20: =IF($K20="To be purchased",COUNTIF($K$2:$K20,"To be purchased"),"")
A21: Power & Switching | B21: E-Stop - NC Contact Block, ZBE-102N MoMa, OST | C21: 10-G E-Stops & Push Buttons | D21: Badri | E21: 4 | F21: India | H21: Yes | J21: =IFERROR(HYPERLINK("https://docs.google.com/spreadsheets/d/10M8oEMfSST-xuPwcSARfQDNcQJ0xrCp8O9iHBGPAr34/edit?gid=1956219685&range=A"&MATCH("PR-2026-1682",'PR Lookup'!A:A,0),"PR-2026-1682"),"PR-2026-1682") | K21: In stock | L21: 10 | M21: FALSE | N21: 5 | S21: Mobile (travels with robot) | U21: 52 | V21: =IF($K21="To be purchased",COUNTIF($K$2:$K21,"To be purchased"),"")
A22: Power & Switching | B22: Push Button - Red, XB5AA45 - TS sander sprayer | C22: 10-G E-Stops & Push Buttons | D22: Uttez | E22: 2 | F22: India | H22: Yes | J22: =IFERROR(HYPERLINK("https://docs.google.com/spreadsheets/d/10M8oEMfSST-xuPwcSARfQDNcQJ0xrCp8O9iHBGPAr34/edit?gid=1956219685&range=A"&MATCH("PR-2026-1620",'PR Lookup'!A:A,0),"PR-2026-1620"),"PR-2026-1620") | K22: In stock | L22: 10 | M22: FALSE | N22: 5 | P22: IQC : Continuity check | S22: Mobile (travels with robot) | T22: Also stocked in: Tool Spares / Sprayer EBOM. Kept separate on purpose - one per box. | U22: 478 | V22: =IF($K22="To be purchased",COUNTIF($K$2:$K22,"To be purchased"),"")
A23: Power & Switching | B23: Push Button - Blue, XB5AA61 - TS sander sprayer | C23: 10-G E-Stops & Push Buttons | D23: Uttez | E23: 2 | F23: India | H23: No | J23: =IFERROR(HYPERLINK("https://docs.google.com/spreadsheets/d/10M8oEMfSST-xuPwcSARfQDNcQJ0xrCp8O9iHBGPAr34/edit?gid=1956219685&range=A"&MATCH("PR-2026-1621",'PR Lookup'!A:A,0),"PR-2026-1621"),"PR-2026-1621") | K23: PR Raised | L23: 10 | M23: FALSE | N23: 5 | S23: Mobile (travels with robot) | T23: Also stocked in: Tool Spares / Sprayer EBOM. Kept separate on purpose - one per box. | U23: 479 | V23: =IF($K23="To be purchased",COUNTIF($K$2:$K23,"To be purchased"),"")
A24: Power & Switching | B24: Push Button - Green, XB5AA31 - TS sander sprayer | C24: 10-G E-Stops & Push Buttons | D24: Uttez | E24: 2 | F24: India | H24: Yes | J24: =IFERROR(HYPERLINK("https://docs.google.com/spreadsheets/d/10M8oEMfSST-xuPwcSARfQDNcQJ0xrCp8O9iHBGPAr34/edit?gid=1956219685&range=A"&MATCH("PR-2026-1622",'PR Lookup'!A:A,0),"PR-2026-1622"),"PR-2026-1622") | K24: In stock | L24: 10 | M24: FALSE | N24: 5 | P24: IQC : Continuity check | S24: Mobile (travels with robot) | T24: Also stocked in: Tool Spares / Sprayer EBOM. Kept separate on purpose - one per box. | U24: 480 | V24: =IF($K24="To be purchased",COUNTIF($K$2:$K24,"To be purchased"),"")
A25: Power & Switching | B25: Push Button - Yellow, XB5AA51 - TS sander sprayer | C25: 10-G E-Stops & Push Buttons | D25: Uttez | E25: 2 | F25: India | H25: Yes | J25: =IFERROR(HYPERLINK("https://docs.google.com/spreadsheets/d/10M8oEMfSST-xuPwcSARfQDNcQJ0xrCp8O9iHBGPAr34/edit?gid=1956219685&range=A"&MATCH("PR-2026-1621",'PR Lookup'!A:A,0),"PR-2026-1621"),"PR-2026-1621") | K25: In stock | L25: 10 | M25: FALSE | N25: 5 | P25: IQC : Continuity check | S25: Mobile (travels with robot) | T25: Also stocked in: Tool Spares / Sprayer EBOM. Kept separate on purpose - one per box. | U25: 481 | V25: =IF($K25="To be purchased",COUNTIF($K$2:$K25,"To be purchased"),"")
A26: Power & Switching | B26: Switch - Toggle, XB5AD21 - EM latch trigger | C26: 10-H Switches | D26: Badri | E26: 1 | F26: India | H26: No | K26: IQC Stage | L26: 10 | M26: FALSE | N26: 5 | S26: Mobile (travels with robot) | U26: 79 | V26: =IF($K26="To be purchased",COUNTIF($K$2:$K26,"To be purchased"),"")
A27: Power & Switching | B27: Switch - Power On, LAK39C-11T | C27: 10-H Switches | D27: Badri | E27: 1 | F27: India | H27: No | J27: =IFERROR(HYPERLINK("https://docs.google.com/spreadsheets/d/10M8oEMfSST-xuPwcSARfQDNcQJ0xrCp8O9iHBGPAr34/edit?gid=1956219685&range=A"&MATCH("PR-2026-1697",'PR Lookup'!A:A,0),"PR-2026-1697"),"PR-2026-1697") | K27: PR Raised | L27: 10 | M27: FALSE | N27: 5 | S27: Mobile (travels with robot) | U27: 131 | V27: =IF($K27="To be purchased",COUNTIF($K$2:$K27,"To be purchased"),"")
A28: Power & Switching | B28: Switch - Power with Integrated LED, LB12E-P10Z - HHM | C28: 10-H Switches | D28: Uttez | E28: 1 | F28: India | H28: No | K28: In stock | L28: 10 | M28: FALSE | N28: 5 | S28: Mobile (travels with robot) | U28: 146 | V28: =IF($K28="To be purchased",COUNTIF($K$2:$K28,"To be purchased"),"")
A29: Power & Switching | B29: Indication Light - 48 V DC, 3EPLBR348DC | C29: 10-I Indication Lights & LEDs | D29: Badri | E29: 1 | F29: India | H29: No | K29: IQC Stage | L29: 10 | M29: FALSE | N29: 5 | S29: NY Stationary (stays in NY inventory) | U29: 47 | V29: =IF($K29="To be purchased",COUNTIF($K$2:$K29,"To be purchased"),"")
A30: Power & Switching | B30: Indication Light - 24 V DC, 3EPLBR3L24DC Green MoMa, OST, TS Sander, TS Sprayer | C30: 10-I Indication Lights & LEDs | D30: Badri | E30: 5 | F30: India | H30: No | K30: In stock | L30: 10 | M30: FALSE | N30: 5 | P30: IQC : 24V DC input, LED Glow | S30: NY Stationary (stays in NY inventory) | U30: 48 | V30: =IF($K30="To be purchased",COUNTIF($K$2:$K30,"To be purchased"),"")
A31: Power & Switching | B31: Indication Light - 240 V AC, 3EPLBR5L240AC | C31: 10-I Indication Lights & LEDs | D31: Badri | E31: 1 | F31: India | H31: No | K31: IQC Stage | L31: 10 | M31: FALSE | N31: 5 | S31: NY Stationary (stays in NY inventory) | U31: 49 | V31: =IF($K31="To be purchased",COUNTIF($K$2:$K31,"To be purchased"),"")
A32: Power & Switching | B32: LED - Perception Light, CMB2550-57E-0A-N0B-00001 | C32: 10-I Indication Lights & LEDs | D32: Badri | E32: 7 | F32: India | H32: No | J32: =IFERROR(HYPERLINK("https://docs.google.com/spreadsheets/d/10M8oEMfSST-xuPwcSARfQDNcQJ0xrCp8O9iHBGPAr34/edit?gid=1956219685&range=A"&MATCH("PR-2026-1633",'PR Lookup'!A:A,0),"PR-2026-1633"),"PR-2026-1633") | K32: PR Raised | L32: 10 | M32: FALSE | N32: 5 | S32: Mobile (travels with robot) | U32: 96 | V32: =IF($K32="To be purchased",COUNTIF($K$2:$K32,"To be purchased"),"")
A33: Power & Switching | B33: Tower Light - 12 V, Q1-A | C33: 10-I Indication Lights & LEDs | D33: Badri | E33: 1 | F33: India | H33: Yes | J33: =IFERROR(HYPERLINK("https://docs.google.com/spreadsheets/d/10M8oEMfSST-xuPwcSARfQDNcQJ0xrCp8O9iHBGPAr34/edit?gid=1956219685&range=A"&MATCH("PR-2026-1698",'PR Lookup'!A:A,0),"PR-2026-1698"),"PR-2026-1698") | K33: PR Raised | L33: 10 | M33: FALSE | N33: 5 | S33: NY Stationary (stays in NY inventory) | U33: 98 | V33: =IF($K33="To be purchased",COUNTIF($K$2:$K33,"To be purchased"),"")
A34: Power & Switching | B34: Enclosure - Sander Latch Indication LED (3D printed) | C34: 10-I Indication Lights & LEDs | D34: SANKALP | E34: 1 | F34: India | H34: No | K34: To be Printed | L34: 10 | M34: FALSE | N34: 5 | Q34: SANDER LATCH INDICATION LED ENCLOSURE | U34: 431 | V34: =IF($K34="To be purchased",COUNTIF($K$2:$K34,"To be purchased"),"")
A35: Power & Switching | B35: LED - CREE XHP70D-00-0000-0D0BP450E - EOA LED Lights with PCBS | C35: 10-I Indication Lights & LEDs | D35: Uttez | E35: 10 | F35: India | H35: Yes | J35: =IFERROR(HYPERLINK("https://docs.google.com/spreadsheets/d/10M8oEMfSST-xuPwcSARfQDNcQJ0xrCp8O9iHBGPAr34/edit?gid=1956219685&range=A"&MATCH("PR-2026-1390",'PR Lookup'!A:A,0),"PR-2026-1390"),"PR-2026-1390") | K35: Payment Done | L35: 10 | M35: FALSE | N35: 5 | P35: IQC : LED glow at 12V DC input | S35: Mobile (travels with robot) | T35: Also stocked in: Tool Spares / Sander EBOM. Kept separate on purpose - one per box. | U35: 442 | V35: =IF($K35="To be purchased",COUNTIF($K$2:$K35,"To be purchased"),"")
A36: Power & Switching | B36: LED - CREE XHP70D-00-0000-0D0BP450E EOA Light Set for Sander Vision | C36: 10-I Indication Lights & LEDs | D36: Uttez | E36: 2 | F36: India | H36: No | K36: To be Prepared | L36: 10 | M36: FALSE | N36: 5 | S36: Mobile (travels with robot) | T36: [POSSIBLE DUPLICATE of source row 442. Previous status: IQC Stage] Also stocked in: Tool Spares / Sprayer EBOM. Kept separate on purpose - one per box. | U36: 455 | V36: =IF($K36="To be purchased",COUNTIF($K$2:$K36,"To be purchased"),"")
A37: Power & Switching | B37: LED - CREE XHP70D-00-0000-0D0BP450E EOA Light Set for Sprayer Vision | C37: 10-I Indication Lights & LEDs | D37: Uttez | E37: 2 | F37: India | H37: No | K37: In stock | L37: 10 | M37: FALSE | N37: 5
A38: Power & Switching | B38: Indicator LED - Red, 3PLBR4L-024 - TS comms / latch, sander & sprayer | C38: 10-I Indication Lights & LEDs | D38: Uttez | E38: 4 | F38: India | H38: Yes | J38: =IFERROR(HYPERLINK("https://docs.google.com/spreadsheets/d/10M8oEMfSST-xuPwcSARfQDNcQJ0xrCp8O9iHBGPAr34/edit?gid=1956219685&range=A"&MATCH("PR-2026-1618",'PR Lookup'!A:A,0),"PR-2026-1618"),"PR-2026-1618") | K38: In stock | L38: 10 | M38: FALSE | N38: 5 | P38: IQC : 24V Input LED GLow | S38: Mobile (travels with robot) | T38: Also stocked in: Tool Spares / Sprayer EBOM. Kept separate on purpose - one per box. | U38: 476 | V38: =IF($K38="To be purchased",COUNTIF($K$2:$K38,"To be purchased"),"")
A39: Power & Switching | B39: Fan - Sunon 80 x 25 mm, 24 V DC - MoMa, OST, TS Sander | C39: 10-J Fans & Cooling | D39: Badri | E39: 5 | F39: India | H39: No | J39: =IFERROR(HYPERLINK("https://docs.google.com/spreadsheets/d/10M8oEMfSST-xuPwcSARfQDNcQJ0xrCp8O9iHBGPAr34/edit?gid=1956219685&range=A"&MATCH("PR-2026-1659",'PR Lookup'!A:A,0),"PR-2026-1659"),"PR-2026-1659") | K39: PR Raised | L39: 10 | M39: FALSE | N39: 5 | S39: Mobile (travels with robot) | U39: 66 | V39: =IF($K39="To be purchased",COUNTIF($K$2:$K39,"To be purchased"),"")
A40: Power & Switching | B40: Fan - Sunon 80 x 25 mm, 12 V DC - cooling | C40: 10-J Fans & Cooling | D40: Badri | E40: 2 | F40: India | H40: No | K40: IQC Stage | L40: 10 | M40: FALSE | N40: 5 | S40: Mobile (travels with robot) | U40: 89 | V40: =IF($K40="To be purchased",COUNTIF($K$2:$K40,"To be purchased"),"")
...
